<!DOCTYPE html>
<html lang="en">
<head>
    <meta charset="UTF-8">
    <meta name="viewport" content="width=device-width, initial-scale=1.0">
    <meta http-equiv="X-UA-Compatible" content="ie=edge">
    <title>Document</title>
</head>
<body>
    <div id="log">aaa</div>
    <script>
        // Promise 对象
        // 4、Promise.prototype.catch()
        // eg: demo1
        // getJSON('/posts.json').then(function(posts) {
        //     // ...
        // }).catch(function(error) {
        //     // 处理 getJSON 和 前一个回调函数运行时发生的错误
        //     console.log('发生错误！', error);
        // });


        // eg： demo2
        // 一般来说，不要在then方法里面定义 Reject 状态的回调函数（即then的第二个参数），总是使用catch方法。
        // bad
        // promise
        //     .then(function(data) {
        //         // success
        //     }, function(err) {
        //     // error
        // });

        // good
        // promise
        //     .then(function(data) { //cb
        //         // success
        //     })
        //     .catch(function(err) {
        //         // error
        //     });
        
        //eg： demo3
        const someAsyncThing = function() {
            return new Promise(function(resolve, reject) {
                // 下面一行会报错，因为x没有声明
                resolve(x + 2);
            });
        };

        someAsyncThing().then(function() {
            console.log('everything is great');
        });

        setTimeout(() => { console.log(123) }, 2000);
        // Uncaught (in promise) ReferenceError: x is not defined
        // 123

        // demo3脚本放在服务器执行，退出码就是0（即表示执行成功）。不过，Node 有一个unhandledRejection事件，专门监听未捕获的reject错误，上面的脚本会触发这个事件的监听函数，可以在监听函数里面抛出错误。

        // process.on('unhandledRejection', function (err, p) {
        //     throw err;
        // });
        // 上面代码中，unhandledRejection事件的监听函数有两个参数，第一个是错误对象，第二个是报错的 Promise 实例，它可以用来了解发生错误的环境信息。
        // 注意，Node 有计划在未来废除unhandledRejection事件。如果 Promise 内部有未捕获的错误，会直接终止进程，并且进程的退出码不为 0。

        
        // 总结：
        // 1、catch方法是Promise对象发生错误时的回调函数，类似于（then(null,reject)的别名）
        // 2、如果Promise对象状态已经为resolved时，那么catch将无法捕获异常，换句话说就是，在状态变为resolved时，在抛出异常是无效的
        // 3、promise对象的错误具有冒泡性质，会一直向后传递，知道捕获为止。也就是说错误总是会被下一个catch捕获
        // 4、捕获异常时使用catch，而不要用then的第二个参数，因为catch可以捕获前面所有then的异常，而then的第二个参数只能捕获当前的then的异常
        // 5、promise内部错误不会影响到外部代码如：demo3
        
    </script>
</body>
</html>