<!DOCTYPE html>
<html lang="en">
<head>
    <meta charset="UTF-8">
    <meta name="viewport" content="width=device-width, initial-scale=1.0">
    <meta http-equiv="X-UA-Compatible" content="ie=edge">
    <title>Document</title>
    <script>
        // Generator 函数的语法
        // 4、Generator.prototype.throw() 
        // 一个简单的生成器并使用 throw方法向该生成器抛出一个异常，该异常通常可以通过 try...catch 块进行捕获.
        // demo1
        function* gen() {
            while(true) {
                try{
                    yield 42;
                }
                catch(e) {
                    console.log('Error caught!')
                }
            }
        }
        var g = gen()
        g.next()
        g.throw('hello world') // Error caught!

        var g2 = function* () {
            try {
                yield;
            } catch (e) {
                console.log('内部捕获', e);
            }
        };

        var i = g2();
        i.next();

        try {
            i.throw('a');
            i.throw('b');
        } catch (e) {
            console.log('外部捕获', e);
        }

        var g3 = function* () {
            try {
                yield;
            } catch (e) {
                console.log(e);
            }
        };

        var i = g3();
        i.next();
        i.throw(new Error('出错了！'));
        // 内部捕获 a
        // 外部捕获 b

        var g4 = function* () {
            while (true) {
                try {
                yield;
                } catch (e) {
                if (e != 'a') throw e;
                console.log('内部捕获', e);
                }
            }
        };

        var i4 = g4();
        i4.next();

        try {
            throw new Error('a');
            throw new Error('b');
        } catch (e) {
            console.log('外部捕获', e);
        }
        // 上面代码之所以只捕获了a，是因为函数体外的catch语句块，捕获了抛出的a错误以后，就不会再继续try代码块里面剩余的语句了。

        var g5 = function* () {
            while (true) {
                yield;
                console.log('内部捕获', e);
            }
        };

        var i5 = g5();
        i5.next();

        try {
            i5.throw('a');
            i5.throw('b');
        } catch (e) {
            console.log('外部捕获', e);
        }
        // 外部捕获 a
        // 上面代码中，Generator 函数g内部没有部署try...catch代码块，所以抛出的错误直接被外部catch代码块捕获。

        // var g6 = function*() {
        //     yield 'hello';
        //     yield 'world';
        // }
        // var i6 = g6();
        // console.log(i6.next());
        // i6.throw(); // Uncaught undefined
        // 上面代码中，g.throw抛出错误以后，没有任何try...catch代码块可以捕获这个错误，导致程序报错，中断执行。

        var g7 = function* (){
            try {
                yield console.log('a');
            } catch (e) {
                // ...
            }
            yield console.log('b');
            yield console.log('c');
        }

        var i7 = g7();
        i7.next() // a
        i7.throw() // b
        i7.next() // c
        // 上面代码中，g.throw方法被捕获以后，自动执行了一次next方法，所以会打印b。另外，也可以看到，只要 Generator 函数内部部署了try...catch代码块，那么遍历器的throw方法抛出的错误，不影响下一次遍历。
        function* g8() {
            yield 1;
            console.log('throwing an exception');
            throw new Error('generator broke!');
            yield 2;
            yield 3;
        }

        function log(generator) {
            var v;
            console.log('starting generator');
            try {
                v = generator.next();
                console.log('第一次运行next方法', v);
            } catch (err) {
                console.log('捕捉错误', v);
            }
            try {
                v = generator.next();
                console.log('第二次运行next方法', v);
            } catch (err) {
                console.log('捕捉错误', v);
            }
            try {
                v = generator.next();
                console.log('第三次运行next方法', v);
            } catch (err) {
                console.log('捕捉错误', v);
            }
            console.log('caller done');
        }

        log(g8());
        // starting generator
        // 第一次运行next方法 { value: 1, done: false }
        // throwing an exception
        // 捕捉错误 { value: 1, done: false }
        // 第三次运行next方法 { value: undefined, done: true }
        // caller done
        // 上面代码一共三次运行next方法，第二次运行的时候会抛出错误，然后第三次运行的时候，Generator 函数就已经结束了，不再执行下去了。

        
        // 总结
        // 1、用来向生成器抛出异常，并恢复生成器的执行，返回带有 done 及 value 两个属性的对象。
        // 2、遍历器连续抛出2个错误，第一个错误会被Generator函数体内的catch捕获；第二个错误由于Generator函数体内的catch已经执行过，不会再捕获这个错误了，所以这个错误被抛出了函数体外，被函数体外的catch捕获
        // 3、throw方法可以接受一个参数，该参数会被catch语句接收，建议抛出Error对象的实例。
        // 4、如果Generator函数内部没有部署try...catch语句，则throw方法抛出错误会直接被外部catch捕获
        // 5、如果Generator函数内部与外部都没有部署catch语句，则程序将报错，中断执行
        // 6、 Generator函数的throw方法被捕获以后，会自动执行一次next方法
        // 7、 只要Generator函数内部部署了try...catch代码块，throw方法抛出的错误不影响下次遍历
        // 8、 throw命令与g.throw方法是无关的，两者互不影响。
        // 9、 一旦 Generator 执行过程中抛出错误，且没有被内部捕获，就不会再执行下去了
        // 注意：不要混淆遍历器对象的throw方法和全局的throw命令。上面代码的错误，是用遍历器对象的throw方法抛出的，而不是用throw命令抛出的。后者只能被函数体外的catch语句捕获。
    </script>
</head>
<body>
    
</body>
</html>